Workbook

Sheet Modelo CFO
B2: BLOQUE A — SUPUESTOS GENERALES PARAMETRIZADOS
B3: Parámetro | C3: Valor | D3: Unidad | E3: Fuente / Nota
B4: Tipo de cambio USD/MXN | C4: 17.1 | D4: MXN/USD
B5: Tarifa eléctrica industrial SLP | C5: 3 | D5: MXN/kWh | E5: Referencia CFE tarifa GDMTH SLP vigente. Verificar cotización actual.
B6: Precio gas LP industrial | C6: 18.5 | D6: MXN/kg | E6: Supuesto razonado
B7: Precio diésel | C7: 24 | D7: MXN/litro | E7: Supuesto razonado
B8: Factor contingencia energética | C8: 1.1 | D8: x
B9: Días operativos al año | C9: 300 | D9: días
B10: Días operativos al mes | C10: 25 | D10: días
B11: Merma estimada | C11: 0.1 | D11: %
B12: Costo renta zona industrial SLP | C12: 65 | D12: MXN/m²/mes
B13: Factor prestaciones sociales | C13: 1.35 | D13: x
B14: WACC | C14: 0.2 | D14: %
B15: Tasa ISR | C15: 0.3 | D15: %
B16: PTU | C16: 0.1 | D16: %
B17: Reserva legal | C17: 0.05 | D17: %
B18: Vida útil maquinaria industrial | C18: 10 | D18: años
B19: Vida útil transporte | C19: 4 | D19: años
... B32: Precio carbono | C32: 8 | D32: USD/tCO₂e
B33: Volumen RSU ciudad (Modelo Base) | C33: 725.76 | E33: Ancla RSU = 725,76 t/día. Valor fijo (antes IMPORTRANGE). Fuente: Modelo_FINAL D43. Revisado 2026-04-12.
B34: Tarifa municipal por tonelada recibida | C34: 0 | E34: MXN/ton | F34: Decisión de negocio: tarifa municipal = $0. No se cobra al municipio en modelo base. Revisado 2026-04-12.
B35: SUPUESTO CLAVE — Costo de adquisición materia prima | C35: 0 | E35: MXN/ton
B36: Múltiplo valor terminal EBITDA | C36: 5 | D36: x | E36: Rango 4-6x
B37: Tasa interés deuda Pequeña | C37: 0.14 | D37: % anual
B38: Tasa interés deuda Mediana | C38: 0.135 | D38: % anual
B39: Tasa interés deuda Grande | C39: 0.13 | D39: % anual
B40: Plazo deuda Pequeña | C40: 4 | D40: años
B41: Plazo deuda Mediana | C41: 6 | D41: años
B42: Plazo deuda Grande | C42: 8 | D42: años
B43: Estructura D/E Pequeña (% deuda) | C43: 0.5 | D43: % | E43: 50/50
B44: Estructura D/E Mediana (% deuda) | C44: 0.6 | D44: % | E44: 60/40
B45: Estructura D/E Grande (% deuda) | C45: 0.7 | D45: % | E45: 70/30
B46: Salario operario (bruto/mes) | C46: 10000 | D46: MXN
B47: Salario supervisor (bruto/mes) | C47: 17500 | D47: MXN
B48: Salario administrativo (bruto/mes) | C48: 25000 | D48: MXN
B49: Salario chofer (bruto/mes) | C49: 13500 | D49: MXN
B50: Personal Pequeña | C50: 4 op + 1 sup | D50: personas
B51: Personal Mediana | C51: 10 op + 2 sup + 1 adm + 1 chof | D51: personas
B52: Personal Grande | C52: 25 op + 4 sup + 2 adm + 3 chof | D52: personas
B53: RSU total ZM SLP (ancla Modelo Base) | C53: 725.76 | D53: t/día | E53: Ancla RSU. Fuente: Modelo_RSUSLP_vivienda_particular_v2-FINAL.xlsx, hoja Modelo, celda D42 = 725,76 t/dia. Actualizar trimestralmente.
...

Sheet Resumen Ejecutivo
B2: RESUMEN EJECUTIVO — CENTROS DE ACOPIO SAN LUIS POTOSÍ
B3: Modelo financiero CFO — Tres escalas
C5: Pequeña | D5: Mediana | E5: Grande
B6: INVERSIÓN
B7: CAPEX total | C7: ='Modelo CFO'!C89 -> 726476.16 | D7: ='Modelo CFO'!D89 -> 2528807.9 | E7: ='Modelo CFO'!E89 -> 7131655.3
B8: Gastos preoperativos | C8: ='Modelo CFO'!C87 -> 45000 | D8: ='Modelo CFO'!D87 -> 65000 | E8: ='Modelo CFO'!E87 -> 95000
B9: Capital de trabajo inicial | C9: ='Modelo CFO'!C88 -> 221676.16 | D9: ='Modelo CFO'!D88 -> 640707.93 | E9: ='Modelo CFO'!E88 -> 1574655.3
B10: Inversión total requerida | C10: ='Modelo CFO'!C89 -> 726476.16 | D10: ='Modelo CFO'!D89 -> 2528807.9 | E10: ='Modelo CFO'!E89 -> 7131655.3
B11: Estructura D/E | C11: 50/50 | D11: 60/40 | E11: 70/30
B12: Capital propio franquiciatario | C12: ='Modelo CFO'!C89*(1-'Modelo CFO'!$C$43) -> 363238.08 | D12: ='Modelo CFO'!D89*(1-'Modelo CFO'!$C$44) -> 1011523.2 | E12: ='Modelo CFO'!E89*(1-'Modelo CFO'!$C$45) -> 2139496.6
B14: RENTABILIDAD
B15: Ingreso mensual Año 1 (50% captura) | C15: ='Modelo CFO'!F118*'Modelo CFO'!$C$26 -> 120444.47 | D15: ='Modelo CFO'!L118*'Modelo CFO'!$C$26 -> 491568.75 | E15: ='Modelo CFO'!R118*'Modelo CFO'!$C$26 -> 1680750
B16: Ingreso mensual Año 3 (100% captura) | C16: ='Modelo CFO'!F118 -> 240888.94 | D16: ='Modelo CFO'!L118 -> 983137.5 | E16: ='Modelo CFO'!R118 -> 3361500
B17: EBITDA Año 3 | C17: ='Modelo CFO'!E129 -> 1560610.3 | D17: ='Modelo CFO'!E148 -> 7953402.4 | E17: ='Modelo CFO'!E167 -> 30890068
B18: Margen EBITDA Año 3 (%) | C18: ='Modelo CFO'!E130 -> 0.53987891 | D18: ='Modelo CFO'!E149 -> 0.67415141 | E18: ='Modelo CFO'!E168 -> 0.76578086
B19: VPN a WACC (20%) | C19: ='Modelo CFO'!C335 -> 4348678 | D19: ='Modelo CFO'!D335 -> 24182707 | E19: ='Modelo CFO'!E335 -> 98482753
B20: TIR del proyecto | C20: ='Modelo CFO'!C333 -> 0.99928693 | D20: ='Modelo CFO'!D333 -> 1.4737121 | E20: ='Modelo CFO'!E333 -> 2.0228523
B21: TIR del equity | C21: ='Modelo CFO'!C334 -> 0.99928693 | D21: ='Modelo CFO'!D334 -> 1.4737121 | E21: ='Modelo CFO'!E334 -> 2.0228523
B22: Payback simple (meses) | C22: ='Modelo CFO'!C336 -> 15.566098 | D22: ='Modelo CFO'!D336 -> 10.808278 | E22: ='Modelo CFO'!E336 -> 7.3719643
B23: Payback descontado (meses) | C23: ='Modelo CFO'!C337 -> 17.9 | D23: ='Modelo CFO'!D337 -> 12.4 | E23: ='Modelo CFO'!E337 -> 8.5
B24: MOIC | C24: ='Modelo CFO'!C338 -> 14.707841 | D24: ='Modelo CFO'!D338 -> 22.50652 | E24: ='Modelo CFO'!E338 -> 31.910252
B26: RIESGO
B27: DSCR mínimo Año 1 | C27: ='Modelo CFO'!D215 -> 5.5081847 | D27: ='Modelo CFO'!D231 -> 8.6881747 | E27: ='Modelo CFO'!D247 -> 12.13278
B28: Break-even kg/día | C28: ='Modelo CFO'!C340 -> 1649.189 | D28: ='Modelo CFO'!D340 -> 4643.3423 | E28: ='Modelo CFO'!E340 -> 11710.957
B29: Margen de seguridad sobre OPEX fijo | C29: ='Modelo CFO'!C341 -> 1.1733409 | D29: ='Modelo CFO'!D341 -> 2.0689101 | E29: ='Modelo CFO'!E341 -> 3.2695059
B30: Ingreso al 50% de captura | C30: ='Modelo CFO'!F118*0.5 -> 120444.47 | D30: ='Modelo CFO'!L118*0.5 -> 491568.75 | E30: ='Modelo CFO'!R118*0.5 -> 1680750
B33: SENSIBILIDAD A TASA DE CAPTURA
B34: Pequeña | C34: 30% | D34: 50% | E34: 70% | F34: 90%
B35: Ingreso mensual | C35: ='Modelo CFO'!C386 -> 72266.681 | D35: ='Modelo CFO'!D386 -> 120444.47 | E35: ='Modelo CFO'!E386 -> 168622.26 | F35: ='Modelo CFO'!F386 -> 216800.04
B36: EBITDA mensual | C36: ='Modelo CFO'!C387 -> -38571.399 | D36: ='Modelo CFO'!D387 -> 9606.3888 | E36: ='Modelo CFO'!E387 -> 57784.176 | F36: ='Modelo CFO'!F387 -> 105961.96
B37: Meses a break-even | C37: ='Modelo CFO'!C388 -> 999 | D37: ='Modelo CFO'!D388 -> 75.624272 | E37: ='Modelo CFO'!E388 -> 12.572234 | F37: ='Modelo CFO'!F388 -> 6.8560088
B39: Mediana | C39: 30% | D39: 50% | E39: 70% | F39: 90%
B40: Ingreso mensual | C40: ='Modelo CFO'!C391 -> 294941.25 | D40: ='Modelo CFO'!D391 -> 491568.75 | E40: ='Modelo CFO'!E391 -> 688196.25 | F40: ='Modelo CFO'!F391 -> 884823.75
B41: EBITDA mensual | C41: ='Modelo CFO'!C392 -> -25412.713 | D41: ='Modelo CFO'!D392 -> 171214.79 | E41: ='Modelo CFO'!E392 -> 367842.29 | F41: ='Modelo CFO'!F392 -> 564469.79
B42: Meses a break-even | C42: ='Modelo CFO'!C393 -> 999 | D42: ='Modelo CFO'!D393 -> 14.769799 | E42: ='Modelo CFO'!E393 -> 6.874707 | F42: ='Modelo CFO'!F393 -> 4.4799704
B44: Grande | C44: 30% | D44: 50% | E44: 70% | F44: 90%
B45: Ingreso mensual | C45: ='Modelo CFO'!C396 -> 1008450 | D45: ='Modelo CFO'!D396 -> 1680750 | E45: ='Modelo CFO'!E396 -> 2353050 | F45: ='Modelo CFO'!F396 -> 3025350
B46: EBITDA mensual | C46: ='Modelo CFO'!C397 -> 221122.37 | D46: ='Modelo CFO'!D397 -> 893422.37 | E46: ='Modelo CFO'!E397 -> 1565722.4 | F46: ='Modelo CFO'!F397 -> 2238022.4
B47: Meses a break-even | C47: ='Modelo CFO'!C398 -> 32.252076 | D47: ='Modelo CFO'!D398 -> 7.9824006 | E47: ='Modelo CFO'!E398 -> 4.5548658 | F47: ='Modelo CFO'!F398 -> 3.186588
B50: Generado: 2026-03-26 | Modelo CFO Centros de Acopio SLP
...

Sheet Datos para Gráficas
A1: TABLA 1 — INVERSIÓN POR ESCALA
A3: Concepto | B3: Pequeña | C3: Mediana | D3: Grande
A4: CAPEX total | B4: 726476 | C4: 2528808 | D4: 7131655
A5: Gastos preoperativos | B5: 45000 | C5: 65000 | D5: 95000
A6: Capital de trabajo inicial | B6: 221676 | C6: 640708 | D6: 1574655
A8: TABLA 2 — OPEX MENSUAL POR ESCALA
A10: Concepto | B10: Pequeña | C10: Mediana | D10: Grande
A11: OPEX mensual total | B11: 110838 | C11: 320354 | D11: 787328
A13: TABLA 3 — RENTABILIDAD POR ESCALA
A14: Concepto | B14: Pequeña | C14: Mediana | D14: Grande
A15: Ingreso mensual Año 1 (50% captura) | B15: 127194 | C15: 511819 | D15: 1748250
A16: Ingreso mensual Año 3 (100% captura) | B16: 254389 | C16: 1023638 | D16: 3496500
A17: EBITDA Año 3 | B17: 1722610 | C17: 8439402 | D17: 32510068
A18: TIR proyecto | B18: 109.5% | C18: 155.6% | D18: 212.0%
A19: Payback simple (meses) | B19: 46126 | C19: 46032 | D19: 7.0
A21: TABLA 4 — INGRESOS POR FRACCIÓN DE MATERIAL (Escala Mediana, Año 3 / 100% captura)
A22: Fracción | B22: Ingreso mensual (MXN)
A23: PET | B23: 208125
A24: Papel/Cartón (OCC) | B24: 116250
A25: Vidrio | B25: 70875
A26: Aluminio | B26: 628388 | L26: el
A28: TABLA 5 — DIMENSIONAMIENTO DEL SISTEMA
A29: Escala | B29: Capacidad unitaria | C29: Unidades | D29: Capacidad total
A30: Pequeña | B30: 5 t/día | C30: 20 | D30: 100 t/día
A31: Mediana | B31: 15 t/día | C31: 8 | D31: 120 t/día
A32: Grande | B32: 50 t/día | C32: 3 | D32: 150 t/día
A33: TOTAL SISTEMA | C33: 31 unidades | D33: 370 t/día

Sheet Modelo Optimizacion
A1: MODELO DE OPTIMIZACIÓN MULTICRITERIO — ARREGLO ÓPTIMO DE CENTROS DE ACOPIO | SAN LUIS POTOSÍ SECCIÓN 1 — PARÁMETROS BASE POR UNIDAD (Ingreso año 3 / 100% captura) Escala Capacidad CAPEX unitario (MXN) OPEX / mes (MXN) Ingreso / mes Yr3 (MXN) EBITDA / mes (MXN) Margen EBITDA VPN unitario (MXN) TIR proyecto Payback (meses) VPN / CAPEX ratio Pequeña (P) 5 t/día 726,476 110,838 254,389 143,551 56.4% 4,932,233 109.5% 14.4 6.79x Mediana (M) 15 t/día 2,528,808 320,354 1,023,638 703,284 68.7% 25,933,373 155.6% 10.1 10.26x Grande (G) 50 t/día 7,131,655 787,328 3,496,500 2,709,172 77.5% 104,318,307 212.0% 7.0 14.63x SECCIÓN 2 — INDICADORES AGREGADOS POR FASE DE ESCALAMIENTO Fase Arreglo CA Peq CA Med CA Gra Total CAs Capacidad t/d CAPEX total (MXN) OPEX / mes total (MXN) Ingreso / mes Yr3 (MXN) EBITDA / mes (MXN) VPN total (MXN) Ratio EBITDA/CAPEX Ratio OPEX/Ingreso 1 — Piloto 3P+0M+0G 3 0 0 3 15 2,179,428 332,514 763,167 430,653 14,796,699 0.1977 0.4358 2 — Arranque 5P+1M+0G 5 1 0 6 40 6,161,188 874,544 2,295,583 1,421,039 50,596,538 0.2306 0.3810 3 — Expansión 5P+3M+0G 5 3 0 8 70 11,224,804 1,515,676 3,342,759 1,827,083 124,405,864 0.1628 0.4535 4 — Consolidación 8P+4M+1G 8 4 1 13 130 22,006,167 3,398,300 9,319,810 5,921,510 286,186,055 0.2691 0.3647 5 — Madurez ★ 10P+6M+2G 10 6 2 18 230 35,520,970 5,662,096 16,011,364 10,349,268 756,663,673 0.2913 0.3537 6 — Sist. completo 20P+8M+3G 20 8 3 31 370 71,853,393 12,178,252 37,095,634 24,917,382 1,598,037,631 0.3468 0.3283 SECCIÓN 3 — MODELO IEC (función objetivo multicriterio) IEC = 0.35×(EBITDA/CAPEX) + 0.25×(1/Payback) + 0.30×(VPN/CAPEX) − 0.10×(OPEX/Ingreso) Fase α·EBITDA/CAPEX (w=0.35) β·1/Payback (w=0.25) γ·VPN/CAPEX (w=0.30) −δ·OPEX/Ingreso (w=0.10) IEC TOTAL Ranking 1 — Piloto 0.0692 0.0174 2.0370 -0.0436 2.0800 6º 2 — Arranque 0.0807 0.0208 2.4695 -0.0381 2.5329 5º 3 — Expansión 0.0570 0.0217 3.3277 -0.0454 3.3610 4º 4 — Consolidación 0.0942 0.0294 3.9070 -0.0365 3.9941 3º 5 — Madurez ★ 0.1019 0.0321 6.3919 -0.0354 6.4905 2º 6 — Sist. completo 0.1214 0.0357 6.6680 -0.0328 6.7923 1º SECCIÓN 4 — MODELO IEMPI (eficiencia marginal por peso invertido) IEMPI = ΔIEC / ΔCAPEX Transición entre fases ΔCAPEX (MXN) ΔIEC IEMPI (×10⁻⁶ / MXN) Señal 1 → 2 3,981,760 0.4529 0.1137 Bueno 2 → 3 5,063,616 0.8281 0.1635 Bueno 3 → 4 10,781,363 0.6331 0.0587 Medio 4 → 5 ★ ÓPTIMO 13,514,803 2.4964 0.1847 ► IEMPI MÁXIMO 5 → 6 36,332,423 0.3018 0.0083 Marginal SECCIÓN 5 — RESULTADO DEL MODELO Indicador Valor Unidad / Nota Arreglo óptimo 10P + 6M + 2G Fase 5 — Madurez Total centros de acopio 18 unidades Capacidad instalada 230 t/día = 31.7% del RSU total SLP CAPEX total requerido $35,520,970 MXN OPEX mensual total $5,662,096 MXN / mes Ingreso mensual (Yr3) $16,011,364 MXN / mes EBITDA mensual $10,349,268 MXN / mes = margen 64.6% VPN del sistema $756,663,673 MXN a WACC 20% IEC del arreglo 6.4905 95.6% del máximo teórico posible IEMPI del salto óptimo 0.1847 Valor más alto de toda la escalera Recicladoras activas 4 Orgánicos + PET + Vidrio + Aluminio CAPEX recicladoras (Fase A) $12,783,523 MXN (Orgánicos + PET + Vidrio + Aluminio) CAPEX total sistema integrado $48,304,493 MXN (CAs Fase 5 + Recicladoras Fase A) | P1: NOTA METODOLÓGICA — MODELO DE OPTIMIZACIÓN MULTICRITERIO OBJETIVO Determinar el arreglo óptimo de centros de acopio (CAs) para el sistema de valorización de residuos sólidos en la Zona Metropolitana de San Luis Potosí, maximizando simultáneamente el retorno sobre la inversión, la eficiencia operativa y la derrama económica, sujeto a restricciones de capital y escala. MODELO 1 — IEC: ÍNDICE DE EFICIENCIA COMPUESTO Se construyó una función objetivo de programación por metas (goal programming) con 4 componentes ponderados: alfa (0.35): Rentabilidad operativa → EBITDA/CAPEX. Mide cuánto genera el sistema por cada peso invertido en activos fijos y capital de trabajo. Ponderación mayor porque es el indicador de viabilidad operativa básica. beta (0.25): Velocidad de recuperación → 1/Payback. Inversamente proporcional al tiempo de retorno. Refleja liquidez del inversionista y gestión de riesgo temporal. gamma (0.30): Creación de valor → VPN/CAPEX. Relaciona el valor presente neto del proyecto con la inversión inicial. Alta ponderación porque captura el impacto de largo plazo sobre la derrama económica regional. delta negativo (0.10): Eficiencia operativa → -OPEX/Ingreso. Penaliza arreglos donde los costos operativos consumen una proporción alta de los ingresos. Ponderación menor porque ya está parcialmente capturada en el margen EBITDA. El IEC crece monótonamente de la Fase 1 a la Fase 6, lo que indica que el sistema completo siempre domina en eficiencia absoluta. Sin embargo, esto por sí solo no responde la pregunta real del inversionista: en qué punto el costo incremental de escalar deja de justificarse. MODELO 2 — IEMPI: EFICIENCIA MARGINAL POR PESO INVERTIDO Para resolver la pregunta de escala óptima se aplicó un segundo modelo de análisis incremental (análisis marginal de costo-beneficio), calculando para cada transición entre fases: IEMPI = delta-IEC / delta-CAPEX Este indicador mide cuántos puntos de eficiencia compuesta (IEC) se ganan por cada peso adicional de inversión. Es el equivalente financiero a la segunda derivada de la función de utilidad: el punto donde la pendiente de retorno comienza a decrecer define el óptimo. RESULTADO Y JUSTIFICACIÓN El IEMPI máximo (0.1847) se produce en la transición de la Fase 4 a la Fase 5, es decir, al pasar de 13 a 18 centros de acopio agregando 2 pequeños, 2 medianos y 1 grande. Esto identifica la Fase 5 (Madurez) como el arreglo óptimo: 10 Centros Pequeños (5 t/d) + 6 Centros Medianos (15 t/d) + 2 Centros Grandes (50 t/d) = 18 CAs / 230 t/d A partir de este punto, la Fase 6 requiere $36.3 M MXN adicionales de CAPEX para ganar solo 0.30 puntos de IEC, un IEMPI de apenas 0.0083, es decir, 22 veces menos eficiente por peso invertido que el salto óptimo 4-a-5. Escalar al sistema completo no está justificado matemáticamente salvo que exista un mandato regulatorio o subsidio público que cambie la estructura de costos. DERRAMA ECONÓMICA El arreglo óptimo de la Fase 5 genera $756.6 M MXN de VPN del sistema, crea empleo directo para aproximadamente 168 personas (10.7 por unidad promedio) y procesa 230 t/d de material reciclable, desviando del relleno sanitario el equivalente a 84,000 t/año de RSU. Activa 4 recicladoras industriales (orgánicos, PET, vidrio y aluminio), multiplicando la cadena de valor local. FUENTES DE LOS PARÁMETROS Todos los datos base (CAPEX, OPEX, ingresos, TIR, VPN) provienen del Modelo_CAPEX_OPEX_Centros_Acopio_v2, hoja Modelo CFO, Bloques A-K. Precios de venta actualizados a marzo 2026 (ANIPAC / CEMPRE México). RSU ancla: 725.76 t/día (Modelo_RSUSLP_vivienda_particular_v2-FINAL, celda D42). WACC: 20%.
B4: Fase | C4: Arreglo | D4: CAs | E4: Cap. t/d | F4: CAPEX total | G4: EBITDA/mes | H4: IEC
B5: 1-Piloto | C5: 3P+0M+0G | D5: 3 | E5: 15 | F5: $2.18 M | G5: $430K | H5: 46236
B6: 2-Arranque | C6: 5P+1M+0G | D6: 6 | E6: 40 | F6: $6.16 M | G6: $1.42 M | H6: 2.53
B7: 3-Expansión | C7: 5P+3M+0G | D7: 8 | E7: 70 | F7: $11.22 M | G7: $1.83 M | H7: 3.61
B8: 4-Consolidación | C8: 8P+4M+1G | D8: 13 | E8: 130 | F8: $22.0 M | G8: $5.92 M | H8: 3.99
B9: 5-Madurez ★ ÓPTIMO | C9: 10P+6M+2G | D9: 18 | E9: 230 | F9: $35.5 M | G9: $10.35 M | H9: 6.49
B10: 6-Sist. completo | C10: 20P+8M+3G | D10: 31 | E10: 370 | F10: $71.9 M | G10: $24.9 M | H10: 6.79
