Workbook

Sheet Resumen Ejecutivo
B2: RESUMEN EJECUTIVO COMPARATIVO — RECICLADORAS POR GIRO — SAN LUIS POTOSÍ
B3: Modelo financiero CFO — Cinco giros × Tres escenarios (40% base)
C4: PET | D4: Papel/Cartón | E4: Aluminio | F4: Vidrio | G4: Orgánicos
B5: INVERSIÓN
B6: CAPEX total | C6: =PET!C64 -> 3840994.8 | D6: ='Papel-Carton'!C63 -> 3396733.8 | E6: =Aluminio!C64 -> 3865004.5 | F6: =Vidrio!C64 -> 1872563.9 | G6: ='Organicos-Composta'!C69 -> 3204959.2
B7: Capital de trabajo | C7: =PET!C63 -> 1514994.8 | D7: ='Papel-Carton'!C62 -> 1517733.8 | E7: =Aluminio!C63 -> 1711204.5 | F7: =Vidrio!C63 -> 562563.94 | G7: ='Organicos-Composta'!C68 -> 991159.18
B8: Inversión total | C8: =PET!C64 -> 3840994.8 | D8: ='Papel-Carton'!C63 -> 3396733.8 | E8: =Aluminio!C64 -> 3865004.5 | F8: =Vidrio!C64 -> 1872563.9 | G8: ='Organicos-Composta'!C69 -> 3204959.2
B9: Estructura D/E | C9: =PET!C29 -> 0.6 | D9: ='Papel-Carton'!C29 -> 0.6 | E9: =Aluminio!C29 -> 0.6 | F9: =Vidrio!C29 -> 0.6 | G9: ='Organicos-Composta'!C29 -> 0.6
B10: Capital propio requerido | C10: =PET!C288 -> 1536397.9 | D10: ='Papel-Carton'!C295 -> 1358693.5 | E10: =Aluminio!C288 -> 1546001.8 | F10: =Vidrio!C287 -> 749025.57 | G10: ='Organicos-Composta'!C296 -> 1281983.7
B12: RENTABILIDAD (Escenario 40% base)
B13: Ingreso mensual Año 1 | C13: =PET!D286 -> 2140810.6 | D13: ='Papel-Carton'!D293 -> 2037934.1 | E13: =Aluminio!D286 -> 2401137 | F13: =Vidrio!D285 -> 475099.91 | G13: ='Organicos-Composta'!D294 -> 274975.2
B14: Ingreso mensual Año 3 | C14: =PET!D287 -> 4281621.1 | D14: ='Papel-Carton'!D294 -> 4075868.2 | E14: =Aluminio!D287 -> 4802274.1 | F14: =Vidrio!D286 -> 950199.83 | G14: ='Organicos-Composta'!D295 -> 549950.4
B15: EBITDA Año 3 | C15: =PET!D280 -> 9956876.5 | D15: ='Papel-Carton'!D287 -> 612975.08 | E15: =Aluminio!D280 -> 10077626 | F15: =Vidrio!D279 -> -1770745.7 | G15: ='Organicos-Composta'!D288 -> 1070928.1
B16: Margen EBITDA Año 3 % | C16: =PET!D281 -> 0.19379102 | D16: ='Papel-Carton'!D288 -> 0.012532608 | E16: =Aluminio!D281 -> 0.17487593 | F16: =Vidrio!D280 -> -0.1552959 | G16: ='Organicos-Composta'!D289 -> 0.16227647
B17: VPN a WACC | C17: =PET!D274 -> 28539880 | D17: ='Papel-Carton'!D281 -> -4449205.3 | E17: =Aluminio!D274 -> 28742303 | F17: =Vidrio!D273 -> -9774471.3 | G17: ='Organicos-Composta'!D282 -> -1982824.8
B18: TIR proyecto | C18: =PET!D275 -> 1.1288502 | D18: ='Papel-Carton'!D282 -> -0.067991804 | E18: =Aluminio!D275 -> 1.1032428 | F18: =Vidrio!D274 -> - | G18: ='Organicos-Composta'!D283 -> 0.08151614
B19: TIR equity | C19: =PET!D276 -> 1.1288502 | D19: ='Papel-Carton'!D283 -> -0.067991804 | E19: =Aluminio!D276 -> 1.1032428 | F19: =Vidrio!D275 -> - | G19: ='Organicos-Composta'!D284 -> 0.08151614
B20: Payback simple (meses) | C20: =PET!D277 -> 15.005511 | D20: ='Papel-Carton'!D284 -> 999 | E20: =Aluminio!D277 -> 15.420765 | F20: =Vidrio!D276 -> 999 | G20: ='Organicos-Composta'!D285 -> 999
B21: Payback descontado (meses) | C21: =PET!D278 -> 17.256337 | D21: ='Papel-Carton'!D285 -> 1148.85 | E21: =Aluminio!D278 -> 17.73388 | F21: =Vidrio!D277 -> 1148.85 | G21: ='Organicos-Composta'!D286 -> 1148.85
B22: MOIC | C22: =PET!D279 -> 16.562315 | D22: ='Papel-Carton'!D286 -> 0.54309141 | E22: =Aluminio!D279 -> 16.104723 | F22: =Vidrio!D278 -> -7.4056923 | G22: ='Organicos-Composta'!D287 -> 1.6859638
B24: RIESGO
B25: DSCR mínimo | C25: =PET!D282 -> 7.1609531 | D25: ='Papel-Carton'!D289 -> 0.49850869 | E25: =Aluminio!D282 -> 7.2027715 | F25: =Vidrio!D281 -> -2.6122273 | G25: ='Organicos-Composta'!D290 -> 0.92305853
B26: Break-even kg/día | C26: =PET!D283 -> 43883.567 | D26: ='Papel-Carton'!D290 -> 143332.87 | E26: =Aluminio!D283 -> 18863.525 | F26: =Vidrio!D282 -> 41923.378 | G26: ='Organicos-Composta'!D291 -> 12130.237
B27: Margen de seguridad | C27: =PET!D284 -> 1.2403732 | D27: ='Papel-Carton'!D291 -> 1.0126917 | E27: =Aluminio!D284 -> 1.2119389 | F27: =Vidrio!D283 -> 0.86557911 | G27: ='Organicos-Composta'!D292 -> 1.1937112
B28: Escenario pesimista 50% captura | C28: =PET!E94*0.5-PET!C79 -> -1311070.9 | D28: ='Papel-Carton'!E93*0.5-'Papel-Carton'!C79 -> -1986852.8 | E28: =Aluminio!E94*0.5-Aluminio!C80 -> -1561334.9 | F28: =Vidrio!E93*0.5-Vidrio!C79 -> -622662.05 | G28: ='Organicos-Composta'!E102*0.5-'Organicos-Composta'!C84 -> -185731.19
B30: TABLA COMPARATIVA POR ESCENARIO × GIRO
C31: PET - | F31: Papel/Cartón | I31: Aluminio | L31: Vidrio | O31: Orgánicos
B32: Métrica | C32: Esc_municipal | D32: Esc_concesionario | E32: Esc_impacto | F32: Esc_municipal | G32: Esc_concesionario | H32: Esc_impacto | I32: Esc_municipal | J32: Esc_concesionario | K32: Esc_impacto | L32: Esc_municipal | M32: Esc_concesionario | N32: Esc_impacto | O32: Esc_municipal | P32: Esc_concesionario | Q32: Esc_impacto
B33: Volumen procesado t/mes | C33: =PET!D86 -> 122.472 | D33: =PET!E86 -> 217.728 | E33: =PET!F86 -> 870.912 | F33: ='Papel-Carton'!D85 -> 326.592 | G33: ='Papel-Carton'!E85 -> 580.608 | H33: ='Papel-Carton'!F85 -> 2322.432 | I33: =Aluminio!D86 -> 51.43824 | J33: =Aluminio!E86 -> 91.44576 | K33: =Aluminio!F86 -> 365.78304 | L33: =Vidrio!D85 -> 81.648 | M33: =Vidrio!E85 -> 145.152 | N33: =Vidrio!F85 -> 580.608 | O33: ='Organicos-Composta'!D90 -> 108.6 | P33: ='Organicos-Composta'!E90 -> 144.8 | Q33: ='Organicos-Composta'!F90 -> 289.6
B34: Ingreso mensual MXN | C34: =PET!D94 -> 2913608.9 | D34: =PET!E94 -> 4281621.1 | E34: =PET!F94 -> 11737716 | F34: ='Papel-Carton'!D93 -> 2905035.8 | G34: ='Papel-Carton'!E93 -> 4075868.2 | H34: ='Papel-Carton'!F93 -> 9771632.6 | I34: =Aluminio!D94 -> 3283817.2 | J34: =Aluminio!E94 -> 4802274.1 | K34: =Aluminio!F94 -> 12995357 | L34: =Vidrio!D93 -> 687577.4 | M34: =Vidrio!E93 -> 950199.83 | N34: =Vidrio!F93 -> 2167839.3 | O34: ='Organicos-Composta'!D102 -> 493912.8 | P34: ='Organicos-Composta'!E102 -> 549950.4 | Q34: ='Organicos-Composta'!F102 -> 774100.8
B35: EBITDA mensual | C35: =PET!D94-PET!C79 -> -538272.53 | D35: =PET!E94-PET!C79 -> 829739.71 | E35: =PET!F94-PET!C79 -> 8285835.1 | F35: ='Papel-Carton'!D93-'Papel-Carton'!C79 -> -1119751.1 | G35: ='Papel-Carton'!E93-'Papel-Carton'!C79 -> 51081.257 | H35: ='Papel-Carton'!F93-'Papel-Carton'!C79 -> 5746845.7 | I35: =Aluminio!D94-Aluminio!C80 -> -678654.72 | J35: =Aluminio!E94-Aluminio!C80 -> 839802.13 | K35: =Aluminio!F94-Aluminio!C80 -> 9032885 | L35: =Vidrio!D93-Vidrio!C79 -> -410184.57 | M35: =Vidrio!E93-Vidrio!C79 -> -147562.14 | N35: =Vidrio!F93-Vidrio!C79 -> 1070077.3 | O35: ='Organicos-Composta'!D102-'Organicos-Composta'!C84 -> 33206.408 | P35: ='Organicos-Composta'!E102-'Organicos-Composta'!C84 -> 89244.008 | Q35: ='Organicos-Composta'!F102-'Organicos-Composta'!C84 -> 313394.41
B36: Meses a break-even | C36: =PET!C277 -> 23.0422 | D36: =PET!D277 -> 15.005511 | E36: =PET!E277 -> 1.9003665 | F36: ='Papel-Carton'!C284 -> 999 | G36: ='Papel-Carton'!D284 -> 999 | H36: ='Papel-Carton'!E284 -> 1.7413674 | I36: =Aluminio!C277 -> 999 | J36: =Aluminio!D277 -> 15.420765 | K36: =Aluminio!E277 -> 1.2507912 | L36: =Vidrio!C276 -> 999 | M36: =Vidrio!D276 -> 999 | N36: =Vidrio!E276 -> 4.8049643 | O36: ='Organicos-Composta'!C285 -> 999 | P36: ='Organicos-Composta'!D285 -> 999 | Q36: ='Organicos-Composta'!E285 -> 38.725392
B37: TIR | C37: =PET!C275 -> 0.80546726 | D37: =PET!D275 -> 1.1288502 | E37: =PET!E275 -> 6.7831833 | F37: ='Papel-Carton'!C282 -> - | G37: ='Papel-Carton'!D282 -> -0.067991804 | H37: ='Papel-Carton'!E282 -> 7.3620998 | I37: =Aluminio!C275 -> - | J37: =Aluminio!D275 -> 1.1032428 | K37: =Aluminio!E275 -> 10.073352 | L37: =Vidrio!C274 -> - | M37: =Vidrio!D274 -> - | N37: =Vidrio!E274 -> 2.922723 | O37: ='Organicos-Composta'!C283 -> -0.12700653 | P37: ='Organicos-Composta'!D283 -> 0.08151614 | Q37: ='Organicos-Composta'!E283 -> 0.55790307
B38: MOIC | C38: =PET!C279 -> 8.8950849 | D38: =PET!D279 -> 16.562315 | E38: =PET!E279 -> 118.58732 | F38: ='Papel-Carton'!C286 -> -25.901764 | G38: ='Papel-Carton'!D286 -> 0.54309141 | H38: ='Papel-Carton'!E286 -> 129.18975 | I38: =Aluminio!C279 -> -14.121674 | J38: =Aluminio!D279 -> 16.104723 | K38: =Aluminio!E279 -> 179.19621 | L38: =Vidrio!C278 -> -19.376764 | M38: =Vidrio!D278 -> -7.4056923 | N38: =Vidrio!E278 -> 48.097751 | O38: ='Organicos-Composta'!C287 -> 0.20360004 | P38: ='Organicos-Composta'!D287 -> 1.6859638 | Q38: ='Organicos-Composta'!E287 -> 7.6154186
B40: Nota: 30% = escenario municipio | 40% = negociación concesionario | 80% = fondos de impacto
B41: Generado: 2026-03-26 21:26 | Actualizada: 2026-04-10 16:00 | Modelo Recicladoras por Giro — Capítulo SLP
B44: DESGLOSE DE REVENUE POR ACTIVIDAD — Escenario 40% base (MXN/mes)
B45: Métrica | C45: PET | D45: Papel/Cartón | E45: Aluminio | F45: Vidrio | G45: Orgánicos
A46: Ingreso Recicladora (valor agregado) | B46: =PET!E88 -> 2961100.8 | C46: =PET!E88 -> 2961100.8 | D46: ='Papel-Carton'!E87 -> 2351462.4 | E46: =Aluminio!E88 -> 3264613.6 | F46: =Vidrio!E87 -> 511457.59 | G46: ='Organicos-Composta'!E96 -> 393856
B47: Ingreso Centro de Acopio (comercialización) | C47: =PET!E91 -> 1796256 | D47: ='Papel-Carton'!E90 -> 2177280 | E47: =Aluminio!E91 -> 2071246.5 | F47: =Vidrio!E90 -> 544320 | G47: ='Organicos-Composta'!E99 -> 217200
...

Sheet Matriz_Compradores


A1: MATRIZ DE COMPRADORES — ECOSISTEMA RSU ZM SLP
A3: SECCIÓN 1 — BLOQUE MAESTRO DE PRECIOS (VERDAD ÚNICA)
A5: Material | B5: Precio_MXN_kg | C5: Fuente | D5: Fecha_referencia | E5: Notas
A6: PET | B6: 5.50 | C6: MB Sección 9 | D6: 2024 | E6: Precio piso recicladora
A7: Papel/Cartón | B7: 2.50 | C7: MB Sección 9 | D7: 2024 | E7: Precio piso recicladora
A8: Vidrio | B8: 1.30 | C8: MB Sección 9 | D8: 2024 | E8: Precio piso recicladora
A9: Aluminio | B9: 46310 | C9: MB Sección 9 | D9: 2024 | E9: Precio piso recicladora
A10: Orgánicos/Composta | B10: 0.80 | C10: MB Sección 9 | D10: 2024 | E10: Estimado composta
A12: SECCIÓN 2 — COMPRADORES ANCLA Y CAPACIDADES
A14: Comprador | B14: Giro | C14: Material_principal | D14: Capacidad_t_mes | E14: Precio_oferta_MXN_kg | F14: Contacto_referencia
A15: Grupo Diarq | B15: Recicladora PET | C15: PET | D15: 300 | E15: 5.50 | F15: Por confirmar
A16: Papelera Moctezuma | B16: Recicladora Papel | C16: Papel/Cartón | D16: 500 | E16: 2.50 | F16: Por confirmar
A17: Vitro / Owens | B17: Recicladora Vidrio | C17: Vidrio | D17: 200 | E17: 1.30 | F17: Por confirmar
A18: Aluminio del Norte | B18: Recicladora Aluminio | C18: Aluminio | D18: 50 | E18: 46310 | F18: Por confirmar
A19: Biocompostaje SLP | B19: Compostador | C19: Orgánicos | D19: 400 | E19: 0.80 | F19: Por confirmar
A21: SECCIÓN 3 — OFERTA POR FASE
A23: Fase | B23: Cobertura_viviendas_% | C23: RSU_t_dia | D23: PET_t_dia | E23: Papel_t_dia | F23: Vidrio_t_dia | G23: Aluminio_t_dia | H23: Organicos_t_dia
A24: 1 | B24: 0.25 | C24: 201.60 | D24: 46307 | E24: 36.29 | F24: 46212 | G24: 6.35 | H24: 138.00
A25: 2 | B25: 0.6 | C25: 483.84 | D25: 46110 | E25: 87.09 | F25: 21.77 | G25: 15.24 | H25: 331.20
A26: 3 | B26: 1 | C26: 806.40 | D26: 48.38 | E26: 145.15 | F26: 36.29 | G26: 25.40 | H26: 552.00
A28: SECCIÓN 4 — HALLAZGOS Y COMPATIBILIDAD
A30: Hallazgo | B30: Detalle | C30: Estatus
A31: Precios EST vs MB | B31: Precios en hoja EST coinciden con MB Sección 9 | C31: VERIFICADO ✓
A32: Precios CAP vs MB | B32: Precios en hoja CAP coinciden con MB Sección 9 | C32: VERIFICADO ✓
A33: Capacidad compradores Fase 1 | B33: Oferta PET 12.1 t/día < Capacidad Diarq 300 t/mes (~10 t/día): compatible | C33: COMPATIBLE ✓
A34: Capacidad compradores Fase 3 | B34: Oferta PET 48.4 t/día > Capacidad ancla actual: requiere 2do comprador | C34: ATENCIÓN ⚠
A35: Vidrio Fase 3 | B35: Oferta 36.3 t/día > Capacidad Vitro/Owens estimada: requiere negociación | C35: ATENCIÓN ⚠
A36: Orgánicos | B36: Mercado composta local en desarrollo; precio 0.80 MXN/kg estimado | C36: POR CONFIRMAR
A37: Discrepancias precios | B37: Cero discrepancias detectadas entre EST, CAP y MB | C37: VERIFICADO ✓

Sheet Dimensionamiento_sistema
A1: MIX ESCALONADO DE RECICLADORAS
A3: Fraccion | B3: % Flujo | C3: t/dia bruto | D3: t/dia neto (post 10%) | E3: t/ano neto | F3: Demanda existente t/ano | G3: GAP t/ano | H3: Nuevas recicladoras necesarias
A4: Organicos | B4: 0.45 | C4: 326.6 | D4: 293.9 | E4: 88179 | F4: 0 | G4: 88179 | H4: Planta composta + biodigestor
A5: Papel/Carton | B5: 0.2 | C5: 145.2 | D5: 130.6 | E5: 39190 | F5: 79200 | G5: 0 | H5: Cubierto por IPSL (79,200 t/a)
A6: PET | B6: 0.15 | C6: 108.9 | D6: 98.0 | E6: 29393 | F6: 5700 | G6: 23693 | H6: 1-2 plantas PET nuevas
A7: Vidrio | B7: 0.05 | C7: 36.3 | D7: 32.7 | E7: 9798 | F7: 0 | G7: 9798 | H7: 1 planta procesamiento vidrio
A8: Aluminio | B8: 0.05 | C8: 36.3 | D8: 32.7 | E8: 9798 | F8: 0 | G8: 9798 | H8: 1 planta fundicion aluminio
A9: Otros (no valorizable) | B9: 0.1 | C9: 72.6 | H9: Disposicion final
A11: TOTAL | B11: 1 | C11: 725.8 | D11: 588.2 | E11: 176358 | F11: 84900 | G11: 131468
A13: ESCALONAMIENTO POR FASE DE COBERTURA
A15: Fraccion | B15: FASE A (25%) t/ano capturado | C15: Demanda existente | D15: GAP A | E15: Recicladoras nuevas A | F15: FASE B (60%) t/ano capturado | G15: GAP B | H15: Recicladoras nuevas B | I15: FASE C (100%) t/ano capturado | J15: GAP C | K15: Recicladoras nuevas C
A16: Organicos | B16: 22045 | C16: 0 | D16: 22045 | E16: 1 | F16: 52907 | G16: 52907 | H16: 2 | I16: 88179 | J16: 88179 | K16: 3
A17: Papel/Carton | B17: 9798 | C17: 79200 | D17: 0 | E17: 0 | F17: 23515 | G17: 0 | H17: 0 | I17: 39190 | J17: 0 | K17: 0
A18: PET | B18: 7348 | C18: 5700 | D18: 1648 | E18: 1 | F18: 17636 | G18: 11936 | H18: 1 | I18: 29393 | J18: 23693 | K18: 2
A19: Vidrio | B19: 2450 | C19: 0 | D19: 2450 | E19: 1 | F19: 5879 | G19: 5879 | H19: 1 | I19: 9798 | J19: 9798 | K19: 2
A20: Aluminio | B20: 2450 | C20: 0 | D20: 2450 | E20: 1 | F20: 5879 | G20: 5879 | H20: 1 | I20: 9798 | J20: 9798 | K20: 2
A22: TOTAL RECICLADORAS | E22: 4 | H22: 4 | K22: 9
A25: SECCIÓN 3 — CAPEX/OPEX AGREGADO POR FASE
A27: Fracción | B27: CAPEX unitario | C27: Recicladoras Fase A | D27: CAPEX Fase A | E27: Recicladoras Fase C | F27: CAPEX Fase C
A28: Orgánicos | B28: 3204959 | C28: 1 | D28: =B28*C28 -> 3204959 | E28: 1 | F28: =B28*E28 -> 3204959
A29: PET | B29: 3840995 | C29: 1 | D29: =B29*C29 -> 3840995 | E29: 1 | F29: =B29*E29 -> 3840995
A30: Vidrio | B30: 1872564 | C30: 1 | D30: =B30*C30 -> 1872564 | E30: 2 | F30: =B30*E30 -> 3745128
A31: Aluminio | B31: 3865005 | C31: 1 | D31: =B31*C31 -> 3865005 | E31: 2 | F31: =B31*E31 -> 7730010
A32: Papel/Cartón | B32: 3396734 | C32: 0 | D32: =B32*C32 -> 0 | E32: 0 | F32: =B32*E32 -> 0
A33: TOTAL | C33: =SUM(C28:C32) -> 4 | D33: =SUM(D28:D32) -> 12783523 | E33: =SUM(E28:E32) -> 6 | F33: =SUM(F28:F32) -> 18521092
A36: PROYECCIÓN EMPLEO AGREGADO
A38: Giro | B38: Empleos por planta | C38: Plantas Fase A | D38: Empleos Fase A | E38: Plantas Fase C | F38: Empleos Fase C
A39: Orgánicos | B39: 20 | C39: 1 | D39: =B39*C39 -> 20 | E39: 1 | F39: =B39*E39 -> 20
A40: PET | B40: 20 | C40: 1 | D40: =B40*C40 -> 20 | E40: 1 | F40: =B40*E40 -> 20
A41: Vidrio | B41: 20 | C41: 1 | D41: =B41*C41 -> 20 | E41: 2 | F41: =B41*E41 -> 40
A42: Aluminio | B42: 20 | C42: 1 | D42: =B42*C42 -> 20 | E42: 2 | F42: =B42*E42 -> 40
A43: Papel/Cartón | B43: 20 | C43: 0 | D43: =B43*C43 -> 0 | E43: 0 | F43: =B43*E43 -> 0
A44: TOTAL | C44: =SUM(C39:C43) -> 4 | D44: =SUM(D39:D43) -> 80 | E44: =SUM(E39:E43) -> 6 | F44: =SUM(F39:F43) -> 120
A46: Factor multiplicador indirecto: 2.5x-3.5x

Sheet Datos para Gráficas
A1: TABLA 1 — TIR POR GIRO (Escenario 40% base)Giro | B1: TIR %
A3: PET | B3: 112.9%
A4: Papel/Cartón | B4: -6.8%
A5: Aluminio | B5: 110.3%
A6: Vidrio | B6: No viable
A7: Orgánicos | B7: 8.2%
A10: TABLA 2 — PAYBACK POR GIRO (Escenario 40%)Giro | B10: Payback (meses)
A12: PET | B12: 15.0
A13: Papel/Cartón | B13: 999.0
A14: Aluminio | B14: 46127
A15: Vidrio | B15: 999.0
A16: Orgánicos | B16: 999.0
A19: TABLA 3 — EBITDA POR GIRO (Año 3, Escenario 40%)Giro | B19: EBITDA Anual (MXN) | C19: Margen %
A21: PET | B21: 9956877 | C21: 19.4%
A22: Papel/Cartón | B22: 612975 | C22: 1.3%
A23: Aluminio | B23: 10077626 | C23: 17.5%
A24: Vidrio | B24: -1770746 | C24: -15.5%
A25: Orgánicos | B25: 1070928 | C25: 16.2%
A28: TABLA 4 — VOLUMEN PROCESADO POR ESCENARIO (t/mes)Giro | B28: 0.3 | C28: 0.4 | D28: 0.8
A30: PET | B30: 122.5 | C30: 217.7 | D30: 870.9
A31: Papel/Cartón | B31: 326.6 | C31: 580.6 | D31: 154224
A32: Aluminio | B32: 51.4 | C32: 91.4 | D32: 365.8
A33: Vidrio | B33: 81.6 | C33: 145.2 | D33: 580.6
A34: Orgánicos | B34: 108.6 | C34: 144.8 | D34: 289.6
A37: TABLA 5 — CAPEX POR GIRO (MXN)Giro | B37: CAPEX Total (MXN)
A39: PET | B39: 3840995
A40: Papel/Cartón | B40: 3396734
A41: Aluminio | B41: 3865005
A42: Vidrio | B42: 1872564
A43: Orgánicos | B43: 3204959
A46: TABLA 6 — COMPOSICIÓN OPEX POR GIRO (Esc 40% mensual, sin CMV, MXN/mes)Giro | B46: Nómina | C46: Energía | D46: Agua/Servicios | E46: Insumos/Químicos | F46: Consumibles | G46: Flete | H46: Mantenimiento | I46: TOTAL
A48: PET | B48: 116775 | C48: 79424 | D48: 4500 | E48: 128449 | F48: 8000 | G48: 380589 | H48: 4315 | I48: 722052
A49: Papel/Cartón | B49: 175500 | C49: 20315 | D49: 4500 | E49: 122276 | F49: 6000 | G49: 362299 | H49: 3217 | I49: 694107
A50: Aluminio | B50: 107325 | C50: 136172 | D50: 3500 | E50: 144068 | F50: 5000 | G50: 426869 | H50: 3560 | I50: 826494
A51: Vidrio | B51: 104625 | C51: 19510 | D51: 3000 | E51: 28506 | F51: 4000 | G51: 84462 | H51: 2156 | I51: 246259
A52: Orgánicos | B52: 186975 | C52: 18506 | D52: 6000 | E52: 16499 | F52: 3000 | G52: 48884 | H52: 3623 | I52: 283487
A55: TABLA 7 — REVE | B55: Revenue por Actividad (MXN/mes, Escenario 40%)
B57: Ingreso Recicladora | C57: Ingreso Centro de Acopio | D57: Ingreso Total Bruto | E57: CMV Compra MP | F57: Margen Bruto
A58: PET | B58: 2961101 | C58: 1796256 | D58: 4757357 | E58: -2694384 | F58: 1587237
A59: Papel/Cartón | B59: 2351462 | C59: 2177280 | D59: 4528742 | E59: -3265920 | F59: 809948
...

Sheet PET
A1: 26
B2: BLOQUE A — SUPUESTOS PARAMETRIZADOS — PET
B3: Parámetro | C3: Valor | D3: Unidad | E3: Fuente / Nota
B4: Tipo de cambio USD/MXN | C4: 17.1 | D4: MXN/USD
B5: Tarifa eléctrica industrial SLP | C5: 3 | D5: MXN/kWh | E5: Ref CFE tarifa GDMTH SLP
B6: Precio gas LP industrial | C6: 18.5 | D6: MXN/kg | E6: Supuesto razonado
B7: Precio diésel | C7: 26 | D7: MXN/litro | E7: Supuesto razonado
B8: Factor contingencia energética | C8: 1.1 | D8: x
B9: Días operativos/año | C9: 300 | D9: días
B10: Días operativos/mes | C10: 25 | D10: días
B11: Merma estimada | C11: 0.1 | D11: % | E11: Teorico
B12: Renta zona industrial | C12: 65 | D12: MXN/m²/mes | E12: teorico
B13: Factor prestaciones sociales | C13: 1.35 | D13: x | E13: teorico
B14: WACC | C14: 0.2 | D14: %
B15: ISR | C15: 0.3 | D15: %
B16: PTU | C16: 0.1 | D16: %
B17: Reserva legal | C17: 0.05 | D17: %
B18: Vida útil maquinaria industrial | C18: 10 | D18: años | E18: teorico
B19: Vida útil transporte | C19: 4 | D19: años
B20: Vida útil cómputo | C20: 3 | D20: años
B21: Factor utilización equipos proceso | C21: 0.75 | D21: %
B22: Capacidad arranque Año 1 | C22: 0.5 | D22: %
B23: Capacidad arranque Año 2 | C23: 0.75 | D23: %
B24: Capacidad arranque Año 3+ | C24: 1 | D24: %
B25: DSO (días cuentas por cobrar) | C25: 30 | D25: días
B26: DIO (días inventario) | C26: 7 | D26: días
B27: DPO (días cuentas por pagar) | C27: 15 | D27: días
B28: Múltiplo valor terminal EBITDA | C28: 5 | D28: x | E28: Rango 4-6x
B29: Estructura D/E (% deuda) | C29: 0.6 | D29: % | E29: 60/40
B30: Tasa interés deuda | C30: 0.135 | D30: % anual
B31: Plazo deuda | C31: 6 | D31: años
B33: Parámetros específicos — PET
B34: Volumen entrada t/mes | C34: 1360.8 | D34: t/mes | E34: Supuesto razonado
B35: Escenario % procesado 30% | C35: 0.3 | D35: % | E35: 30%=municipio
B36: Escenario % procesado 40% | C36: 0.4 | D36: % | E36: 40%=concesionario
B37: Escenario % procesado 80% | C37: 0.8 | D37: % | E37: 80%=fondos de impacto
B38: Rendimiento proceso kg/kg entrada | C38: 0.85 | D38: kg/kg
B39: Precio PET procesado | C39: 16 | D39: MXN/kg | E39: Valor agregado
B40: Precio compra MP centros de acopio (PET) | C40: 5.5 | D40: MXN/kg | E40: Precio compra en centros de acopio
B41: Nave industrial m² | C41: 300 | D41: m²
...

Sheet Papel-Carton
B2: BLOQUE A — SUPUESTOS PARAMETRIZADOS — PAPEL-CARTON
B3: Parámetro | C3: Valor | D3: Unidad | E3: Fuente / Nota
B4: Tipo de cambio USD/MXN | C4: 17.1 | D4: MXN/USD
B5: Tarifa eléctrica industrial SLP | C5: 3 | D5: MXN/kWh | E5: Ref CFE tarifa GDMTH SLP
B6: Precio gas LP industrial | C6: 18.5 | D6: MXN/kg | E6: Supuesto razonado
B7: Precio diésel | C7: 26 | D7: MXN/litro | E7: Supuesto razonado
B8: Factor contingencia energética | C8: 1.1 | D8: x
B9: Días operativos/año | C9: 300 | D9: días
B10: Días operativos/mes | C10: 25 | D10: días
B11: Merma estimada | C11: 0.1 | D11: %
B12: Renta zona industrial | C12: 65 | D12: MXN/m²/mes
B13: Factor prestaciones sociales | C13: 1.35 | D13: x
B14: WACC | C14: 0.2 | D14: %
B15: ISR | C15: 0.3 | D15: %
B16: PTU | C16: 0.1 | D16: %
B17: Reserva legal | C17: 0.05 | D17: %
B18: Vida útil maquinaria industrial | C18: 10 | D18: años
B19: Vida útil transporte | C19: 4 | D19: años
... B27: DPO (días cuentas por pagar) | C27: 15 | D27: días
B28: Múltiplo valor terminal EBITDA | C28: 5 | D28: x | E28: Rango 4-6x
B29: Estructura D/E (% deuda) | C29: 0.6 | D29: % | E29: 60/40
B30: Tasa interés deuda | C30: 0.135 | D30: % anual
B31: Plazo deuda | C31: 6 | D31: años
B33: Parámetros específicos — Papel-Carton
B34: Volumen entrada t/mes | C34: 3628.8 | D34: t/mes | E34: Supuesto razonado
B35: Escenario % procesado 30% | C35: 0.3 | D35: % | E35: =$C$34*C35 -> 1088.64 | G35: Se asume que del 100% recolectado el 10% se perdera en trayecto y se quedara en los camiones, luego de ese 90%, asumimos, que los recicaldores podran comprarlo a 2,5 y procesarlo para despues comercializarlo , se crearon 3 escenarios de aprovechamiento, el 30%, 40% y 80%.
B36: Escenario % procesado 40% | C36: 0.4 | D36: % | E36: =$C$34*C36 -> 1451.52
B37: Escenario % procesado 80% | C37: 0.8 | D37: % | E37: =$C$34*C37 -> 2903.04
B38: Rendimiento proceso kg/kg entrada | C38: 0.9 | D38: kg/kg
B39: Precio Papel-Carton procesado | C39: 4.5 | D39: MXN/kg | E39: Valor agregado
B40: Precio compra MP centros de acopio (Papel-Cartón) | C40: 2.5 | D40: MXN/kg
B41: Nave industrial m² | C41: 600 | D41: m²
B42: Nómina mensual (8 operarios + 2 supervisores + 1 chofer) | C42: 175500 | D42: MXN/mes | E42: (8*10000+2*17500+1*13500)*1.35
B43: Compradores ancla | C43: MRS Logística SLP, Grupo Altsa, Bio Pappel Monterrey | E43: Condiciones: humedad <12%, sin cartón bituminoso
B44: Transporte/combustible mensual | C44: 25000 | D44: MXN/mes | E44: Supuesto operativo (volumen mayor Papel-Cartón)
B45: Agua y servicios mensual | C45: 4500 | D45: MXN/mes | E45: Supuesto operativo
B46: BLOQUE B — CAPEX CON CONSUMOS ENERGÉTICOS — PAPEL-CARTON
B47: Equipo | C47: Marca/Modelo | D47: Cant | E47: Precio unit MXN | F47: Total MXN | G47: kW nominal | H47: Factor util% | I47: Horas efect/día | J47: Días/mes | K47: kWh/mes | L47: kWh×1.10 | M47: Costo MXN/mes | N47: Nota
B48: Prensa embaladora horizontal 5t/h | C48: TEVA/Imabe | D48: 1 | E48: 680000 | F48: =D48*E48 -> 680000 | G48: 22 | H48: 0.75 | I48: =H48*8 -> 6 | J48: =C10 -> 25 | K48: =G48*I48*J48*D48 -> 3300 | L48: =K48*C8 -> 3630 | M48: =L48*C5 -> 10890
B49: Guillotina/Trituradora cartón | C49: Nacional | D49: 1 | E49: 280000 | F49: =D49*E49 -> 280000 | G49: 15 | H49: 0.7 | I49: =H49*8 -> 5.6 | J49: =C10 -> 25 | K49: =G49*I49*J49*D49 -> 2100 | L49: =K49*C8 -> 2310 | M49: =L49*C5 -> 6930
...

Sheet Aluminio
B2: BLOQUE A — SUPUESTOS PARAMETRIZADOS — ALUMINIO
B3: Parámetro | C3: Valor | D3: Unidad | E3: Fuente / Nota
B4: Tipo de cambio USD/MXN | C4: 17.1 | D4: MXN/USD
B5: Tarifa eléctrica industrial SLP | C5: 3 | D5: MXN/kWh | E5: Ref CFE tarifa GDMTH SLP
B6: Precio gas LP industrial | C6: 18.5 | D6: MXN/kg | E6: Supuesto razonado
B7: Precio diésel | C7: 26 | D7: MXN/litro | E7: Supuesto razonado
B8: Factor contingencia energética | C8: 1.1 | D8: x
B9: Días operativos/año | C9: 300 | D9: días
B10: Días operativos/mes | C10: 25 | D10: días
B11: Merma estimada | C11: 0.1 | D11: %
B12: Renta zona industrial | C12: 65 | D12: MXN/m²/mes
B13: Factor prestaciones sociales | C13: 1.35 | D13: x
B14: WACC | C14: 0.2 | D14: %
B15: ISR | C15: 0.3 | D15: %
B16: PTU | C16: 0.1 | D16: %
B17: Reserva legal | C17: 0.05 | D17: %
B18: Vida útil maquinaria industrial | C18: 10 | D18: años
B19: Vida útil transporte | C19: 4 | D19: años
... B27: DPO (días cuentas por pagar) | C27: 15 | D27: días
B28: Múltiplo valor terminal EBITDA | C28: 5 | D28: x | E28: Rango 4-6x
B29: Estructura D/E (% deuda) | C29: 0.6 | D29: % | E29: 60/40
B30: Tasa interés deuda | C30: 0.135 | D30: % anual
B31: Plazo deuda | C31: 6 | D31: años
B33: Parámetros específicos — Aluminio
B34: Volumen entrada t/mes | C34: 571.536 | D34: t/mes | E34: Supuesto razonado
B35: Escenario % procesado 30% | C35: 0.3 | D35: % | E35: 30%=municipio
B36: Escenario % procesado 40% | C36: 0.4 | D36: % | E36: 40%=concesionario
B37: Escenario % procesado 80% | C37: 0.8 | D37: % | E37: 80%=fondos de impacto
B38: Rendimiento proceso kg/kg entrada | C38: 0.85 | D38: kg/kg
B39: Precio Aluminio procesado | C39: 42 | D39: MXN/kg | E39: Valor agregado
B40: Precio compra MP centros de acopio (Aluminio) | C40: 15.1 | D40: MXN/kg
B41: Nave industrial m² | C41: 250 | D41: m²
B42: Nómina mensual (5 operarios + 1 supervisor + 1 fundidor especialista) | C42: 107325 | D42: MXN/mes | E42: (5*10000+1*17500+1*22000)*1.35
B43: Compradores ancla | C43: RRECIMETSA, ARZYZ, industria metalmecánica SLP | E43: Pureza ≥98% Al, sin pintura ni recubrimientos
B44: Transporte/combustible mensual | C44: 12000 | D44: MXN/mes | E44: Supuesto operativo
B45: Agua y servicios mensual | C45: 3500 | D45: MXN/mes | E45: Supuesto operativo
B46: BLOQUE B — CAPEX CON CONSUMOS ENERGÉTICOS — ALUMINIO
B47: Equipo | C47: Marca/Modelo | D47: Cant | E47: Precio unit MXN | F47: Total MXN | G47: kW nominal | H47: Factor util% | I47: Horas efect/día | J47: Días/mes | K47: kWh/mes | L47: kWh×1.10 | M47: Costo MXN/mes | N47: Nota
B48: Horno fundición aluminio 300kg/carga | C48: Nacional/Importado | D48: 1 | E48: 1200000 | F48: =D48*E48 -> 1200000 | G48: 90 | H48: 0.65 | I48: =H48*8 -> 5.2 | J48: =C10 -> 25 | K48: =G48*I48*J48*D48 -> 11700 | L48: =K48*C8 -> 12870 | M48: =L48*C5 -> 38610 | N48: Usa gas LP: 18 kg/hora
B49: Prensa compactadora aluminio | C49: Genérica | D49: 1 | E49: 280000 | F49: =D49*E49 -> 280000 | G49: 22 | H49: 0.7 | I49: =H49*8 -> 5.6 | J49: =C10 -> 25 | K49: =G49*I49*J49*D49 -> 3080 | L49: =K49*C8 -> 3388 | M49: =L49*C5 -> 10164
...

Sheet Vidrio
B2: BLOQUE A — SUPUESTOS PARAMETRIZADOS — VIDRIO
B3: Parámetro | C3: Valor | D3: Unidad | E3: Fuente / Nota
B4: Tipo de cambio USD/MXN | C4: 17.1 | D4: MXN/USD
B5: Tarifa eléctrica industrial SLP | C5: 3 | D5: MXN/kWh | E5: Ref CFE tarifa GDMTH SLP
B6: Precio gas LP industrial | C6: 18.5 | D6: MXN/kg | E6: Supuesto razonado
B7: Precio diésel | C7: 26 | D7: MXN/litro | E7: Supuesto razonado
B8: Factor contingencia energética | C8: 1.1 | D8: x
B9: Días operativos/año | C9: 300 | D9: días
B10: Días operativos/mes | C10: 25 | D10: días
B11: Merma estimada | C11: 0.1 | D11: %
B12: Renta zona industrial | C12: 65 | D12: MXN/m²/mes
B13: Factor prestaciones sociales | C13: 1.35 | D13: x
B14: WACC | C14: 0.2 | D14: %
B15: ISR | C15: 0.3 | D15: %
B16: PTU | C16: 0.1 | D16: %
B17: Reserva legal | C17: 0.05 | D17: %
B18: Vida útil maquinaria industrial | C18: 10 | D18: años
B19: Vida útil transporte | C19: 4 | D19: años
... B27: DPO (días cuentas por pagar) | C27: 15 | D27: días
B28: Múltiplo valor terminal EBITDA | C28: 5 | D28: x | E28: Rango 4-6x
B29: Estructura D/E (% deuda) | C29: 0.6 | D29: % | E29: 60/40
B30: Tasa interés deuda | C30: 0.135 | D30: % anual
B31: Plazo deuda | C31: 6 | D31: años
B33: Parámetros específicos — Vidrio
B34: Volumen entrada t/mes | C34: 907.2 | D34: t/mes | E34: Supuesto razonado
B35: Escenario % procesado 30% | C35: 0.3 | D35: % | E35: 30%=municipio
B36: Escenario % procesado 40% | C36: 0.4 | D36: % | E36: 40%=concesionario
B37: Escenario % procesado 80% | C37: 0.8 | D37: % | E37: 80%=fondos de impacto
B38: Rendimiento proceso kg/kg entrada | C38: 0.92 | D38: kg/kg
B39: Precio cullet transparente | C39: 4.5 | D39: MXN/kg
B40: Precio cullet verde | C40: 2.8 | D40: MXN/kg
B41: Precio cullet ámbar | C41: 3.2 | D41: MXN/kg
B42: Precio compra MP centros de acopio (Vidrio) | C42: 2.5 | D42: MXN/kg
B43: Precio procesado promedio ponderado | C43: 3.83 | D43: MXN/kg | E43: 40%×$4.50+35%×$3.20+25%×$2.80
B44: Nave industrial m² | C44: 300 | D44: m²
B45: Nómina mensual (6 operarios + 1 supervisor) | C45: 104625 | D45: MXN/mes | E45: (6*10000+1*17500)*1.35
B46: Compradores ancla | C46: Vidriera Monterrey (OWENS-ILLINOIS), Vitro, Grupo Altsa | E46: Pureza mínima 98% por color, máx 0.5% metales
B47: Transporte/combustible mensual | C47: 15000 | D47: MXN/mes | E47: Supuesto operativo
B48: Agua y servicios mensual | C48: 3000 | D48: MXN/mes | E48: Supuesto operativo
B49: BLOQUE B — CAPEX CON CONSUMOS ENERGÉTICOS — VIDRIO
...

Sheet Organicos-Composta
B2: BLOQUE A — SUPUESTOS PARAMETRIZADOS — ORGANICOS-COMPOSTA
B3: Parámetro | C3: Valor | D3: Unidad | E3: Fuente / Nota
B4: Tipo de cambio USD/MXN | C4: 17.1 | D4: MXN/USD
B5: Tarifa eléctrica industrial SLP | C5: 3 | D5: MXN/kWh | E5: Ref CFE tarifa GDMTH SLP
B6: Precio gas LP industrial | C6: 18.5 | D6: MXN/kg | E6: Supuesto razonado
B7: Precio diésel | C7: 26 | D7: MXN/litro | E7: Supuesto razonado
B8: Factor contingencia energética | C8: 1.1 | D8: x
B9: Días operativos/año | C9: 300 | D9: días
B10: Días operativos/mes | C10: 25 | D10: días
B11: Merma estimada | C11: 0.1 | D11: %
B12: Renta zona industrial | C12: 65 | D12: MXN/m²/mes
B13: Factor prestaciones sociales | C13: 1.35 | D13: x
B14: WACC | C14: 0.2 | D14: %
B15: ISR | C15: 0.3 | D15: %
B16: PTU | C16: 0.1 | D16: %
B17: Reserva legal | C17: 0.05 | D17: %
B18: Vida útil maquinaria industrial | C18: 10 | D18: años
B19: Vida útil transporte | C19: 4 | D19: años
... B27: DPO (días cuentas por pagar) | C27: 15 | D27: días
B28: Múltiplo valor terminal EBITDA | C28: 5 | D28: x | E28: Rango 4-6x
B29: Estructura D/E (% deuda) | C29: 0.6 | D29: % | E29: 60/40
B30: Tasa interés deuda | C30: 0.135 | D30: % anual
B31: Plazo deuda | C31: 6 | D31: años
B33: Parámetros específicos — Organicos-Composta
B34: Volumen entrada t/mes | C34: 362 | D34: t/mes | E34: Supuesto razonado
B35: Escenario % procesado 30% | C35: 0.3 | D35: % | E35: 30%=municipio
B36: Escenario % procesado 40% | C36: 0.4 | D36: % | E36: 40%=concesionario
B37: Escenario % procesado 80% | C37: 0.8 | D37: % | E37: 80%=fondos de impacto
B38: Rendimiento composta kg/kg entrada | C38: 0.4 | D38: kg/kg | E38: Pérdida humedad en proceso
B39: Precio bolsa 5kg | C39: 45 | D39: MXN/bolsa
B40: Precio bolsa 20kg | C40: 120 | D40: MXN/bolsa
B41: Precio bulto 50kg | C41: 220 | D41: MXN/bulto
B42: Precio compra MP centros de acopio (Orgánicos) | C42: 1 | D42: MXN/kg | E42: Precio compra orgánicos en centros de acopio
B43: Precio orgánico a granel | C43: 1 | D43: MXN/kg | E43: Precio venta a granel agricultura. Ref. mercado SLP 0.80-1.20/kg a granel, 1.50-4.00/kg ensacado retail. Vigencia abr-2026. Revisar trimestralmente con compradores locales (viveros, huertas, proyectos agroecológicos).
B44: Mix ventas 5kg | C44: 0.4 | D44: %
B45: Mix ventas 20kg | C45: 0.35 | D45: %
B46: Mix ventas 50kg | C46: 0.25 | D46: %
B47: Capital de trabajo | C47: 3 | D47: meses OPEX | E47: Proceso 60-90 días
B48: Nave industrial m² | C48: 400 | D48: m²
B49: Nómina mensual ( 10 operarios + 1 supervisor + 1 técnico agronómico) | C49: 186975 | D49: MXN/mes | E49: (10*10000+1*17500+1*20000)*1.35
...
